Workbook

Sheet ПЛК СТАБУР 05-24 CODESYS
A1: 12.03.2026 Прайс лист на продукцию ПЛК/ПО/ПК СТАБУР ООО ПО «Промсвязь»
A2: Примеры полного условного обозначения прибора: ПЛК СТАБУР 21 – программируемый логический контроллер СТАБУР с экраном размером 21,5'', без модулей ввода-вывода и без корзины для их установки. Предустановленная среда исполнения CODESYS 3.5. ПЛК СТАБУР 05 (ETH232+AI+AO+PS24+WIFIBT+DI+DOOC+X) – программируемый логический контроллер СТАБУР с экраном размером 5'', с одной корзиной для модулей с установленными модулями: в слоте №1 – ETH232, №2 – AI №3 – AO, №4 – PS24, №5 – WIFIBT, №6 – DI, №7 – DOOC. В слоте №8 модули отсутствуют. Предустановленная среда исполнения CODESYS 3.5. ПЛК СТАБУР 17 (GSM+X+AI+AO+WIFIBT+X+DI+DOOC+DOS+DOS+DOR+DOR+CAN+TERM+TERM+X) – программируемый логический контроллер СТАБУР с экраном размером 17'', с двумя корзинами для модулей, с установленными модулями: в слоте №1 – GSM, №3 – AI, №4 – AO, №5 – WIFIBT, №7 – DI, №8 – DOOC, №9 и №10 – DOS, №11 и №12 – DOR, №13 – CAN, №14 и №15 – TERM. В слотах №2, №6 и №16 модули отсутствуют. Предустановленная среда исполнения CODESYS 3.5.
A3: Модель | B3: Описание | C3: Цена без НДС | D3: Цена С НДС 22%
A4: ПЛК СТАБУР 05 (Х+Х+Х+PS24+Х+Х+Х+Х) | B4: Программируемый логический контроллер ПЛК СТАБУР 05 (Х+Х+Х+PS24+Х+Х+Х+Х), Пластиковый корпус. Процессор 4х-ядерный ARM v8.2-A Cortex-A55, 64 бит, 2 ГГц; Видеоускоритель Mali-G52; ОЗУ 1 ГБ DDR4 1600 МГц 2 канала; FLASH память 4ГБ eMMC HS200; 1x слот microSD, 1x мини-USB OTG, часы реального времени. Дисплей 5.0'' TFT (800х480). Модуль расширения PS24 — модуль питания 24В установлен в слот №4. Корпус для крепления на щит, габаритные размеры, мм 140x140x88. Возможность установки до 7 модулей расширения. Предустановленная среда исполнения CODESYS 3.5 | C4: 27200 | D4: =C4*1.22 -> 33184
A5: ПЛК СТАБУР 05 4/32 (Х+Х+Х+PS24+Х+Х+Х+Х) | B5: Программируемый логический контроллер ПЛК СТАБУР 05 (Х+Х+Х+PS24+Х+Х+Х+Х), Пластиковый корпус. Процессор 4х-ядерный ARM v8.2-A Cortex-A55, 64 бит, 2 ГГц; Видеоускоритель Mali-G52; ОЗУ 4 ГБ DDR4 1600 МГц 2 канала; FLASH память 32 ГБ eMMC HS200; 1x слот microSD, 1x мини-USB OTG, часы реального времени. Дисплей 5.0'' TFT (800х480). Модуль расширения PS24 — модуль питания 24В установлен в слот №4. Корпус для крепления на щит, габаритные размеры, мм 140x140x88. Возможность установки до 7 модулей расширения. Предустановленная среда исполнения CODESYS 3.5 | C5: 37200 | D5: =C5*1.22 -> 45384
A6: ПЛК СТАБУР 07 (Х+Х+Х+PS24+Х+Х+Х+Х) | B6: Программируемый логический контроллер ПЛК СТАБУР 07 (Х+Х+Х+PS24+Х+Х+Х+Х), Пластиковый корпус. Процессор 4х-ядерный ARM v8.2-A Cortex-A55, 64 бит, 2 ГГц; Видеоускоритель Mali-G52; ОЗУ 1 ГБ DDR4 1600 МГц 2 канала; FLASH память 4ГБ eMMC HS200; 1x слот microSD, 1x мини-USB OTG, часы реального времени. Дисплей 7.0'' TFT (800х480). Модуль расширения PS24 — модуль питания 24В установлен в слот №4.Корпус для крепления на щит, габаритные размеры, мм 185х160х91. Возможность установки до 7 модулей расширения. Предустановленная среда исполнения CODESYS 3.5 | C6: 35000 | D6: =C6*1.22 -> 42700
A7: ПЛК СТАБУР 07 4/32 (Х+Х+Х+PS24+Х+Х+Х+Х) | B7: Программируемый логический контроллер ПЛК СТАБУР 07 (Х+Х+Х+PS24+Х+Х+Х+Х), Пластиковый корпус. Процессор 4х-ядерный ARM v8.2-A Cortex-A55, 64 бит, 2 ГГц; Видеоускоритель Mali-G52; ОЗУ 4 ГБ DDR4 1600 МГц 2 канала; FLASH память 32 ГБ eMMC HS200; 1x слот microSD, 1x мини-USB OTG, часы реального времени. Дисплей 7.0'' TFT (800х480). Модуль расширения PS24 — модуль питания 24В установлен в слот №4.Корпус для крепления на щит, габаритные размеры, мм 185х160х91. Возможность установки до 7 модулей расширения. Предустановленная среда исполнения CODESYS 3.5 | C7: 45000 | D7: =C7*1.22 -> 54900
A8: ПЛК СТАБУР 10 | B8: Программируемый логический контроллер ПЛК СТАБУР 10. Металлический корпус. Процессор 4х-ядерный ARM v8.2-A Cortex-A55, 64 бит, 2 ГГц; Видеоускоритель Mali-G52; ОЗУ 1 ГБ DDR4 1600 МГц 2 канала; FLASH память 4ГБ eMMC HS200; 1x слот microSD, 1x мини-USB OTG, часы реального времени. Дисплей 10.4'' TFT (1024х768); корпус для крепления на щит или на кронштейн 75х75 (VESA), габаритные размеры, мм 289х210х58, интерфейсы 1х Ethernet 10/100, 1х RS-232, 3х RS-485, 1х USB 2.0 HOST, 1х аудио вход, 1х аудио выход. Без корзин для модулей расширения. Предустановленная среда исполнения CODESYS 3.5 | C8: 49000 | D8: =C8*1.22 -> 59780
A9: ПЛК СТАБУР 10 4/32 | B9: Программируемый логический контроллер ПЛК СТАБУР 10. Металлический корпус. Процессор 4х-ядерный ARM v8.2-A Cortex-A55, 64 бит, 2 ГГц; Видеоускоритель Mali-G52; ОЗУ 4 ГБ DDR4 1600 МГц 2 канала; FLASH память 32 ГБ eMMC HS200; 1x слот microSD, 1x мини-USB OTG, часы реального времени. Дисплей 10.4'' TFT (1024х768); корпус для крепления на щит или на кронштейн 75х75 (VESA), габаритные размеры, мм 289х210х58, интерфейсы 1х Ethernet 10/100, 1х RS-232, 3х RS-485, 1х USB 2.0 HOST, 1х аудио вход, 1х аудио выход. Без корзин для модулей расширения. Предустановленная среда исполнения CODESYS 3.5 | C9: 59000 | D9: =C9*1.22 -> 71980
A10: ПЛК СТАБУР 10 (Х+Х+Х+PS24+Х+Х+Х+Х) | B10: Программируемый логический контроллер ПЛК СТАБУР 10 (Х+Х+Х+PS24+Х+Х+Х+Х), Пластиковый корпус. Процессор 4х-ядерный ARM v8.2-A Cortex-A55, 64 бит, 2 ГГц; Видеоускоритель Mali-G52; ОЗУ 1 ГБ DDR4 1600 МГц 2 канала; FLASH память 4ГБ eMMC HS200; 1x слот microSD, 1x мини-USB OTG, часы реального времени. Дисплей 10.1'' TFT (1024х600). Модуль расширения PS24 — модуль питания 24В установлен в слот №4.Корпус для крепления на щит, габаритные размеры, мм 260х210х93. Возможность установки до 7 модулей расширения. Предустановленная среда исполнения CODESYS 3.5 | C10: 42000 | D10: =C10*1.22 -> 51240
A11: ПЛК СТАБУР 10 4/32 (Х+Х+Х+PS24+Х+Х+Х+Х) | B11: Программируемый логический контроллер ПЛК СТАБУР 10 (Х+Х+Х+PS24+Х+Х+Х+Х), Пластиковый корпус. Процессор 4х-ядерный ARM v8.2-A Cortex-A55, 64 бит, 2 ГГц; Видеоускоритель Mali-G52; ОЗУ 4 ГБ DDR4 1600 МГц 2 канала; FLASH память 32 ГБ eMMC HS200; 1x слот microSD, 1x мини-USB OTG, часы реального времени. Дисплей 10.1'' TFT (1024х600). Модуль расширения PS24 — модуль питания 24В установлен в слот №4.Корпус для крепления на щит, габаритные размеры, мм 260х210х93. Возможность установки до 7 модулей расширения. Предустановленная среда исполнения CODESYS 3.5 | C11: 52000 | D11: =C11*1.22 -> 63440
A12: ПЛК СТАБУР 12 | B12: Программируемый логический контроллер ПЛК СТАБУР 12. Металлический корпус. Процессор 4х-ядерный ARM v8.2-A Cortex-A55, 64 бит, 2 ГГц; Видеоускоритель Mali-G52; ОЗУ 1 ГБ DDR4 1600 МГц 2 канала; FLASH память 4ГБ eMMC HS200; 1x слот microSD, 1x мини-USB OTG, часы реального времени. Дисплей 12.1'' TFT (1024х768); корпус для крепления на щит или на кронштейн 75х75 (VESA), габаритные размеры, мм 293х267х45, интерфейсы 1х Ethernet 10/100, 1х RS-232, 3х RS-485, 1х USB 2.0 HOST, 1х аудио вход, 1х аудио выход. Без корзин для модулей расширения. Предустановленная среда исполнения CODESYS 3.5 | C12: 53750 | D12: =C12*1.22 -> 65575
A13: ПЛК СТАБУР 12 4/32 | B13: Программируемый логический контроллер ПЛК СТАБУР 12. Металлический корпус. Процессор 4х-ядерный ARM v8.2-A Cortex-A55, 64 бит, 2 ГГц; Видеоускоритель Mali-G52; ОЗУ 4 ГБ DDR4 1600 МГц 2 канала; FLASH память 32 ГБ eMMC HS200; 1x слот microSD, 1x мини-USB OTG, часы реального времени. Дисплей 12.1'' TFT (1024х768); корпус для крепления на щит или на кронштейн 75х75 (VESA), габаритные размеры, мм 293х267х45, интерфейсы 1х Ethernet 10/100, 1х RS-232, 3х RS-485, 1х USB 2.0 HOST, 1х аудио вход, 1х аудио выход. Без корзин для модулей расширения. Предустановленная среда исполнения CODESYS 3.5 | C13: 63750 | D13: =C13*1.22 -> 77775
A14: ПЛК СТАБУР 12 (Х+Х+Х+Х+Х+Х+Х+Х) | B14: Программируемый логический контроллер ПЛК СТАБУР 12. Процессор 4х-ядерный ARM v8.2-A Cortex-A55, 64 бит, 2 ГГц; Видеоускоритель Mali-G52; ОЗУ 1 ГБ DDR4 1600 МГц 2 канала; FLASH память 4ГБ eMMC HS200; 1x слот microSD, 1x мини-USB OTG, часы реального времени. Дисплей 12.1'' TFT (1024х768); корпус для крепления на щит, габаритные размеры, мм 293х267х94, интерфейсы 1х Ethernet 10/100, 1х RS-232, 3х RS-485, 1х USB 2.0 HOST, 1х аудио вход, 1х аудио выход. 1 корзина на 8 модулей расширения. Предустановленная среда исполнения CODESYS 3.5 | C14: 53750 | D14: =C14*1.22 -> 65575
A15: ПЛК СТАБУР 12 4/32 (Х+Х+Х+Х+Х+Х+Х+Х) | B15: Программируемый логический контроллер ПЛК СТАБУР 12. Процессор 4х-ядерный ARM v8.2-A Cortex-A55, 64 бит, 2 ГГц; Видеоускоритель Mali-G52; ОЗУ 4 ГБ DDR4 1600 МГц 2 канала; FLASH память 32 ГБ eMMC HS200; 1x слот microSD, 1x мини-USB OTG, часы реального времени. Дисплей 12.1'' TFT (1024х768); корпус для крепления на щит, габаритные размеры, мм 293х267х94, интерфейсы 1х Ethernet 10/100, 1х RS-232, 3х RS-485, 1х USB 2.0 HOST, 1х аудио вход, 1х аудио выход. 1 корзина на 8 модулей расширения. Предустановленная среда исполнения CODESYS 3.5 | C15: 63750 | D15: =C15*1.22 -> 77775
... A47: ПЛК СТАБУР 24 4/32 (Х+Х+Х+Х+Х+Х+Х+Х+Х+Х+Х+Х+Х+Х+Х+Х) | B47: Программируемый логический контроллер ПЛК СТАБУР 24. Процессор 4х-ядерный ARM v8.2-A Cortex-A55, 64 бит, 2 ГГц; Видеоускоритель Mali-G52; ОЗУ 4 ГБ DDR4 1600 МГц 2 канала; FLASH память 32 ГБ eMMC HS200; 1x слот microSD, 1x мини-USB OTG, часы реального времени. Дисплей 24'' TFT (1920х1080); корпус для крепления на щит, интерфейсы 1х Ethernet 10/100, 1х RS-232, 3х RS-485, 1х USB 2.0 HOST, 1х аудио вход, 1х аудио выход. 2 корзины по 8 модулей расширения. Предустановленная среда исполнения CODESYS 3.5 | C47: 134500 | D47: =C47*1.22 -> 164090

Sheet ПЛК СТАБУР 05-24 MasterSCADA 4D
A1: ='ПЛК СТАБУР 05-24 CODESYS'!A1 -> 12.03.2026 Прайс лист на продукцию ПЛК/ПО/ПК СТАБУР ООО ПО «Промсвязь»
A2: Примеры полного условного обозначения прибора: ПЛК СТАБУР 21.M0K5 – программируемый логический контроллер СТАБУР с экраном размером 21,5'', без модулей ввода-вывода и без корзины для их установки. Предустановленная среда исполнения MasterSCADA 4D на 500 точек. ПЛК СТАБУР 05.M2K5 (ETH232+AI+AO+PS24+WIFIBT+DI+DOOC+X) – программируемый логический контроллер СТАБУР с экраном размером 5'', с одной корзиной для модулей с установленными модулями: в слоте №1 – ETH232, №2 – AI №3 – AO, №4 – PS24, №5 – WIFIBT, №6 – DI, №7 – DOOC. В слоте №8 модули отсутствуют. Предустановленная среда исполнения MasterSCADA 4D на 2500 точек. ПЛК СТАБУР 17.M5K0 (GSM+X+AI+AO+WIFIBT+X+DI+DOOC+DOS+DOS+DOR+DOR+CAN+TERM+TERM+X) – программируемый логический контроллер СТАБУР с экраном размером 17'', с двумя корзинами для модулей, с установленными модулями: в слоте №1 – GSM, №3 – AI, №4 – AO, №5 – WIFIBT, №7 – DI, №8 – DOOC, №9 и №10 – DOS, №11 и №12 – DOR, №13 – CAN, №14 и №15 – TERM. В слотах №2, №6 и №16 модули отсутствуют. Предустановленная среда исполнения MasterSCADA 4D на 5000 точек.
A3: Модель | B3: Описание | C3: Цена без НДС | D3: Цена С НДС 22%
A4: ПЛК СТАБУР 05.М0K5 (Х+Х+Х+PS24+Х+Х+Х+Х) | B4: Программируемый логический контроллер ПЛК СТАБУР 05 (Х+Х+Х+PS24+Х+Х+Х+Х), Пластиковый корпус. Процессор 4х-ядерный ARM v8.2-A Cortex-A55, 64 бит, 2 ГГц; Видеоускоритель Mali-G52; ОЗУ 1 ГБ DDR4 1600 МГц 2 канала; FLASH память 4ГБ eMMC HS200; 1x слот microSD, 1x мини-USB OTG, часы реального времени. Дисплей 5.0'' TFT (800х480). Модуль расширения PS24 — модуль питания 24В установлен в слот №4. Корпус для крепления на щит, габаритные размеры, мм 140x140x88. Возможность установки до 7 модулей расширения. Предустановленная среда исполнения MasterSCADA 4D комплектация базовая на 500 точек | C4: 42200 | D4: =C4*1.22 -> 51484
A5: ПЛК СТАБУР 05.М0K5 4/32 (Х+Х+Х+PS24+Х+Х+Х+Х) | B5: Программируемый логический контроллер ПЛК СТАБУР 05 (Х+Х+Х+PS24+Х+Х+Х+Х), Пластиковый корпус. Процессор 4х-ядерный ARM v8.2-A Cortex-A55, 64 бит, 2 ГГц; Видеоускоритель Mali-G52; ОЗУ 4 ГБ DDR4 1600 МГц 2 канала; FLASH память 32 ГБ eMMC HS200; 1x слот microSD, 1x мини-USB OTG, часы реального времени. Дисплей 5.0'' TFT (800х480). Модуль расширения PS24 — модуль питания 24В установлен в слот №4. Корпус для крепления на щит, габаритные размеры, мм 140x140x88. Возможность установки до 7 модулей расширения. Предустановленная среда исполнения MasterSCADA 4D комплектация базовая на 500 точек | C5: 52200 | D5: =C5*1.22 -> 63684
A6: ПЛК СТАБУР 05.М1K0 (Х+Х+Х+PS24+Х+Х+Х+Х) | B6: Программируемый логический контроллер ПЛК СТАБУР 05 (Х+Х+Х+PS24+Х+Х+Х+Х), Пластиковый корпус. Процессор 4х-ядерный ARM v8.2-A Cortex-A55, 64 бит, 2 ГГц; Видеоускоритель Mali-G52; ОЗУ 1 ГБ DDR4 1600 МГц 2 канала; FLASH память 4ГБ eMMC HS200; 1x слот microSD, 1x мини-USB OTG, часы реального времени. Дисплей 5.0'' TFT (800х480). Модуль расширения PS24 — модуль питания 24В установлен в слот №4. Корпус для крепления на щит, габаритные размеры, мм 140x140x88. Возможность установки до 7 модулей расширения. Предустановленная среда исполнения MasterSCADA 4D комплектация базовая на 1000 точек | C6: 48200 | D6: =C6*1.22 -> 58804
A7: ПЛК СТАБУР 05.М1K0 4/32 (Х+Х+Х+PS24+Х+Х+Х+Х) | B7: Программируемый логический контроллер ПЛК СТАБУР 05 (Х+Х+Х+PS24+Х+Х+Х+Х), Пластиковый корпус. Процессор 4х-ядерный ARM v8.2-A Cortex-A55, 64 бит, 2 ГГц; Видеоускоритель Mali-G52; ОЗУ 4 ГБ DDR4 1600 МГц 2 канала; FLASH память 32 ГБ eMMC HS200; 1x слот microSD, 1x мини-USB OTG, часы реального времени. Дисплей 5.0'' TFT (800х480). Модуль расширения PS24 — модуль питания 24В установлен в слот №4. Корпус для крепления на щит, габаритные размеры, мм 140x140x88. Возможность установки до 7 модулей расширения. Предустановленная среда исполнения MasterSCADA 4D комплектация базовая на 1000 точек | C7: 58200 | D7: =C7*1.22 -> 71004
A8: ПЛК СТАБУР 05.М2K5 (Х+Х+Х+PS24+Х+Х+Х+Х) | B8: Программируемый логический контроллер ПЛК СТАБУР 05 (Х+Х+Х+PS24+Х+Х+Х+Х), Пластиковый корпус. Процессор 4х-ядерный ARM v8.2-A Cortex-A55, 64 бит, 2 ГГц; Видеоускоритель Mali-G52; ОЗУ 1 ГБ DDR4 1600 МГц 2 канала; FLASH память 4ГБ eMMC HS200; 1x слот microSD, 1x мини-USB OTG, часы реального времени. Дисплей 5.0'' TFT (800х480). Модуль расширения PS24 — модуль питания 24В установлен в слот №4. Корпус для крепления на щит, габаритные размеры, мм 140x140x88. Возможность установки до 7 модулей расширения. Предустановленная среда исполнения MasterSCADA 4D комплектация базовая на 2500 точек | C8: 54200 | D8: =C8*1.22 -> 66124
A9: ПЛК СТАБУР 05.М2K5 4/32 (Х+Х+Х+PS24+Х+Х+Х+Х) | B9: Программируемый логический контроллер ПЛК СТАБУР 05 (Х+Х+Х+PS24+Х+Х+Х+Х), Пластиковый корпус. Процессор 4х-ядерный ARM v8.2-A Cortex-A55, 64 бит, 2 ГГц; Видеоускоритель Mali-G52; ОЗУ 4 ГБ DDR4 1600 МГц 2 канала; FLASH память 32 ГБ eMMC HS200; 1x слот microSD, 1x мини-USB OTG, часы реального времени. Дисплей 5.0'' TFT (800х480). Модуль расширения PS24 — модуль питания 24В установлен в слот №4. Корпус для крепления на щит, габаритные размеры, мм 140x140x88. Возможность установки до 7 модулей расширения. Предустановленная среда исполнения MasterSCADA 4D комплектация базовая на 2500 точек | C9: 64200 | D9: =C9*1.22 -> 78324
A10: ПЛК СТАБУР 05.М5K0 (Х+Х+Х+PS24+Х+Х+Х+Х) | B10: Программируемый логический контроллер ПЛК СТАБУР 05 (Х+Х+Х+PS24+Х+Х+Х+Х), Пластиковый корпус. Процессор 4х-ядерный ARM v8.2-A Cortex-A55, 64 бит, 2 ГГц; Видеоускоритель Mali-G52; ОЗУ 1 ГБ DDR4 1600 МГц 2 канала; FLASH память 4ГБ eMMC HS200; 1x слот microSD, 1x мини-USB OTG, часы реального времени. Дисплей 5.0'' TFT (800х480). Модуль расширения PS24 — модуль питания 24В установлен в слот №4. Корпус для крепления на щит, габаритные размеры, мм 140x140x88. Возможность установки до 7 модулей расширения. Предустановленная среда исполнения MasterSCADA 4D комплектация базовая на 5000 точек | C10: 60200 | D10: =C10*1.22 -> 73444
A11: ПЛК СТАБУР 05.М5K0 4/32 (Х+Х+Х+PS24+Х+Х+Х+Х) | B11: Программируемый логический контроллер ПЛК СТАБУР 05 (Х+Х+Х+PS24+Х+Х+Х+Х), Пластиковый корпус. Процессор 4х-ядерный ARM v8.2-A Cortex-A55, 64 бит, 2 ГГц; Видеоускоритель Mali-G52; ОЗУ 4 ГБ DDR4 1600 МГц 2 канала; FLASH память 32 ГБ eMMC HS200; 1x слот microSD, 1x мини-USB OTG, часы реального времени. Дисплей 5.0'' TFT (800х480). Модуль расширения PS24 — модуль питания 24В установлен в слот №4. Корпус для крепления на щит, габаритные размеры, мм 140x140x88. Возможность установки до 7 модулей расширения. Предустановленная среда исполнения MasterSCADA 4D комплектация базовая на 5000 точек | C11: 70200 | D11: =C11*1.22 -> 85644
A12: ПЛК СТАБУР 05.М10К 4/32 (Х+Х+Х+PS24+Х+Х+Х+Х) | B12: Программируемый логический контроллер ПЛК СТАБУР 05 (Х+Х+Х+PS24+Х+Х+Х+Х), Пластиковый корпус. Процессор 4х-ядерный ARM v8.2-A Cortex-A55, 64 бит, 2 ГГц; Видеоускоритель Mali-G52; ОЗУ 4 ГБ DDR4 1600 МГц 2 канала; FLASH память 32 ГБ eMMC HS200; 1x слот microSD, 1x мини-USB OTG, часы реального времени. Дисплей 5.0'' TFT (800х480). Модуль расширения PS24 — модуль питания 24В установлен в слот №4. Корпус для крепления на щит, габаритные размеры, мм 140x140x88. Возможность установки до 7 модулей расширения. Предустановленная среда исполнения MasterSCADA 4D комплектация базовая на 10000 точек | E12: по запросу
A13: ПЛК СТАБУР 07.М0K5 (Х+Х+Х+PS24+Х+Х+Х+Х) | B13: Программируемый логический контроллер ПЛК СТАБУР 07 (Х+Х+Х+PS24+Х+Х+Х+Х), Пластиковый корпус. Процессор 4х-ядерный ARM v8.2-A Cortex-A55, 64 бит, 2 ГГц; Видеоускоритель Mali-G52; ОЗУ 1 ГБ DDR4 1600 МГц 2 канала; FLASH память 4ГБ eMMC HS200; 1x слот microSD, 1x мини-USB OTG, часы реального времени. Дисплей 7.0'' TFT (800х480). Модуль расширения PS24 — модуль питания 24В установлен в слот №4.Корпус для крепления на щит, габаритные размеры, мм 185х160х91. Возможность установки до 7 модулей расширения. Предустановленная среда исполнения MasterSCADA 4D комплектация базовая на 500 точек, | C13: 50000 | D13: =C13*1.22 -> 61000
A14: ПЛК СТАБУР 07.М0K5 4/32 (Х+Х+Х+PS24+Х+Х+Х+Х) | B14: Программируемый логический контроллер ПЛК СТАБУР 07 (Х+Х+Х+PS24+Х+Х+Х+Х), Пластиковый корпус. Процессор 4х-ядерный ARM v8.2-A Cortex-A55, 64 бит, 2 ГГц; Видеоускоритель Mali-G52; ОЗУ 4 ГБ DDR4 1600 МГц 2 канала; FLASH память 32 ГБ eMMC HS200; 1x слот microSD, 1x мини-USB OTG, часы реального времени. Дисплей 7.0'' TFT (800х480). Модуль расширения PS24 — модуль питания 24В установлен в слот №4.Корпус для крепления на щит, габаритные размеры, мм 185х160х91. Возможность установки до 7 модулей расширения. Предустановленная среда исполнения MasterSCADA 4D комплектация базовая на 500 точек, | C14: 60000 | D14: =C14*1.22 -> 73200
A15: ПЛК СТАБУР 07.М1K0 (Х+Х+Х+PS24+Х+Х+Х+Х) | B15: Программируемый логический контроллер ПЛК СТАБУР 07 (Х+Х+Х+PS24+Х+Х+Х+Х), Пластиковый корпус. Процессор 4х-ядерный ARM v8.2-A Cortex-A55, 64 бит, 2 ГГц; Видеоускоритель Mali-G52; ОЗУ 1 ГБ DDR4 1600 МГц 2 канала; FLASH память 4ГБ eMMC HS200; 1x слот microSD, 1x мини-USB OTG, часы реального времени. Дисплей 7.0'' TFT (800х480). Модуль расширения PS24 — модуль питания 24В установлен в слот №4.Корпус для крепления на щит, габаритные размеры, мм 185х160х91. Возможность установки до 7 модулей расширения. Предустановленная среда исполнения MasterSCADA 4D комплектация базовая на 1000 точек, клиент визуализации | C15: 56000 | D15: =C15*1.22 -> 68320
A16: ПЛК СТАБУР 07.М1K0 4/32 (Х+Х+Х+PS24+Х+Х+Х+Х) | B16: Программируемый логический контроллер ПЛК СТАБУР 07 (Х+Х+Х+PS24+Х+Х+Х+Х), Пластиковый корпус. Процессор 4х-ядерный ARM v8.2-A Cortex-A55, 64 бит, 2 ГГц; Видеоускоритель Mali-G52; ОЗУ 4 ГБ DDR4 1600 МГц 2 канала; FLASH память 32 ГБ eMMC HS200; 1x слот microSD, 1x мини-USB OTG, часы реального времени. Дисплей 7.0'' TFT (800х480). Модуль расширения PS24 — модуль питания 24В установлен в слот №4.Корпус для крепления на щит, габаритные размеры, мм 185х160х91. Возможность установки до 7 модулей расширения. Предустановленная среда исполнения MasterSCADA 4D комплектация базовая на 1000 точек, клиент визуализации | C16: 66000 | D16: =C16*1.22 -> 80520
A17: ПЛК СТАБУР 07.М2K5 (Х+Х+Х+PS24+Х+Х+Х+Х) | B17: Программируемый логический контроллер ПЛК СТАБУР 07 (Х+Х+Х+PS24+Х+Х+Х+Х), Пластиковый корпус. Процессор 4х-ядерный ARM v8.2-A Cortex-A55, 64 бит, 2 ГГц; Видеоускоритель Mali-G52; ОЗУ 1 ГБ DDR4 1600 МГц 2 канала; FLASH память 4ГБ eMMC HS200; 1x слот microSD, 1x мини-USB OTG, часы реального времени. Дисплей 7.0'' TFT (800х480). Модуль расширения PS24 — модуль питания 24В установлен в слот №4.Корпус для крепления на щит, габаритные размеры, мм 185х160х91. Возможность установки до 7 модулей расширения. Предустановленная среда исполнения MasterSCADA 4D комплектация базовая на 2500 точек, клиент визуализации | C17: 62000 | D17: =C17*1.22 -> 75640
A18: ПЛК СТАБУР 07.М2K5 4/32 (Х+Х+Х+PS24+Х+Х+Х+Х) | B18: Программируемый логический контроллер ПЛК СТАБУР 07 (Х+Х+Х+PS24+Х+Х+Х+Х), Пластиковый корпус. Процессор 4х-ядерный ARM v8.2-A Cortex-A55, 64 бит, 2 ГГц; Видеоускоритель Mali-G52; ОЗУ 1 ГБ DDR4 1600 МГц 2 канала; FLASH память 4ГБ eMMC HS200; 1x слот microSD, 1x мини-USB OTG, часы реального времени. Дисплей 7.0'' TFT (800х480). Модуль расширения PS24 — модуль питания 24В установлен в слот №4.Корпус для крепления на щит, габаритные размеры, мм 185х160х91. Возможность установки до 7 модулей расширения. Предустановленная среда исполнения MasterSCADA 4D комплектация базовая на 2500 точек, клиент визуализации | C18: 72000 | D18: =C18*1.22 -> 87840
A19: ПЛК СТАБУР 07.М5K0 (Х+Х+Х+PS24+Х+Х+Х+Х) | B19: Программируемый логический контроллер ПЛК СТАБУР 07 (Х+Х+Х+PS24+Х+Х+Х+Х), Пластиковый корпус. Процессор 4х-ядерный ARM v8.2-A Cortex-A55, 64 бит, 2 ГГц; Видеоускоритель Mali-G52; ОЗУ 1 ГБ DDR4 1600 МГц 2 канала; FLASH память 4ГБ eMMC HS200; 1x слот microSD, 1x мини-USB OTG, часы реального времени. Дисплей 7.0'' TFT (800х480). Модуль расширения PS24 — модуль питания 24В установлен в слот №4.Корпус для крепления на щит, габаритные размеры, мм 185х160х91. Возможность установки до 7 модулей расширения. Предустановленная среда исполнения MasterSCADA 4D комплектация базовая на 5000 точек, клиент визуализации | C19: 68000 | D19: =C19*1.22 -> 82960
A20: ПЛК СТАБУР 07.М5K0 4/32 (Х+Х+Х+PS24+Х+Х+Х+Х) | B20: Программируемый логический контроллер ПЛК СТАБУР 07 (Х+Х+Х+PS24+Х+Х+Х+Х), Пластиковый корпус. Процессор 4х-ядерный ARM v8.2-A Cortex-A55, 64 бит, 2 ГГц; Видеоускоритель Mali-G52; ОЗУ 4 ГБ DDR4 1600 МГц 2 канала; FLASH память 32 ГБ eMMC HS200; 1x слот microSD, 1x мини-USB OTG, часы реального времени. Дисплей 7.0'' TFT (800х480). Модуль расширения PS24 — модуль питания 24В установлен в слот №4.Корпус для крепления на щит, габаритные размеры, мм 185х160х91. Возможность установки до 7 модулей расширения. Предустановленная среда исполнения MasterSCADA 4D комплектация базовая на 5000 точек, клиент визуализации | C20: 78000 | D20: =C20*1.22 -> 95160
A21: ПЛК СТАБУР 07.М10К 4/32 (Х+Х+Х+PS24+Х+Х+Х+Х) | B21: Программируемый логический контроллер ПЛК СТАБУР 07 (Х+Х+Х+PS24+Х+Х+Х+Х), Пластиковый корпус. Процессор 4х-ядерный ARM v8.2-A Cortex-A55, 64 бит, 2 ГГц; Видеоускоритель Mali-G52; ОЗУ 4 ГБ DDR4 1600 МГц 2 канала; FLASH память 32 ГБ eMMC HS200; 1x слот microSD, 1x мини-USB OTG, часы реального времени. Дисплей 7.0'' TFT (800х480). Модуль расширения PS24 — модуль питания 24В установлен в слот №4.Корпус для крепления на щит, габаритные размеры, мм 185х160х91. Возможность установки до 7 модулей расширения. Предустановленная среда исполнения MasterSCADA 4D комплектация базовая на 10000 точек, клиент визуализации | E21: по запросу
A22: ПЛК СТАБУР 10.М0K5 | B22: Программируемый логический контроллер ПЛК СТАБУР 10. Металлический корпус. Процессор 4х-ядерный ARM v8.2-A Cortex-A55, 64 бит, 2 ГГц; Видеоускоритель Mali-G52; ОЗУ 1 ГБ DDR4 1600 МГц 2 канала; FLASH память 4ГБ eMMC HS200; 1x слот microSD, 1x мини-USB OTG, часы реального времени. Дисплей 10.4'' TFT (1024х768); корпус для крепления на щит или на кронштейн 75х75 (VESA), габаритные размеры, мм 289х210х58, интерфейсы 1х Ethernet 10/100, 1х RS-232, 3х RS-485, 1х USB 2.0 HOST, 1х аудио вход, 1х аудио выход. Без корзин для модулей расширения. Предустановленная среда исполнения MasterSCADA 4D комплектация базовая на 500 точек, клиент визуализации | C22: 64000 | D22: =C22*1.22 -> 78080
A23: ПЛК СТАБУР 10.М0K5 4/32 | B23: Программируемый логический контроллер ПЛК СТАБУР 10. Металлический корпус. Процессор 4х-ядерный ARM v8.2-A Cortex-A55, 64 бит, 2 ГГц; Видеоускоритель Mali-G52; ОЗУ 4 ГБ DDR4 1600 МГц 2 канала; FLASH память 32 ГБ eMMC HS200; 1x слот microSD, 1x мини-USB OTG, часы реального времени. Дисплей 10.4'' TFT (1024х768); корпус для крепления на щит или на кронштейн 75х75 (VESA), габаритные размеры, мм 289х210х58, интерфейсы 1х Ethernet 10/100, 1х RS-232, 3х RS-485, 1х USB 2.0 HOST, 1х аудио вход, 1х аудио выход. Без корзин для модулей расширения. Предустановленная среда исполнения MasterSCADA 4D комплектация базовая на 500 точек, клиент визуализации | C23: 74000 | D23: =C23*1.22 -> 90280
A24: ПЛК СТАБУР 10.М1K0 | B24: Программируемый логический контроллер ПЛК СТАБУР 10. Металлический корпус. Процессор 4х-ядерный ARM v8.2-A Cortex-A55, 64 бит, 2 ГГц; Видеоускоритель Mali-G52; ОЗУ 1 ГБ DDR4 1600 МГц 2 канала; FLASH память 4ГБ eMMC HS200; 1x слот microSD, 1x мини-USB OTG, часы реального времени. Дисплей 10.4'' TFT (1024х768); корпус для крепления на щит или на кронштейн 75х75 (VESA), габаритные размеры, мм 289х210х58, интерфейсы 1х Ethernet 10/100, 1х RS-232, 3х RS-485, 1х USB 2.0 HOST, 1х аудио вход, 1х аудио выход. Без корзин для модулей расширения. Предустановленная среда исполнения MasterSCADA 4D комплектация базовая на 1000 точек, клиент визуализации | C24: 70000 | D24: =C24*1.22 -> 85400
A25: ПЛК СТАБУР 10.М1K0 4/32 | B25: Программируемый логический контроллер ПЛК СТАБУР 10. Металлический корпус. Процессор 4х-ядерный ARM v8.2-A Cortex-A55, 64 бит, 2 ГГц; Видеоускоритель Mali-G52; ОЗУ 4 ГБ DDR4 1600 МГц 2 канала; FLASH память 32 ГБ eMMC HS200; 1x слот microSD, 1x мини-USB OTG, часы реального времени. Дисплей 10.4'' TFT (1024х768); корпус для крепления на щит или на кронштейн 75х75 (VESA), габаритные размеры, мм 289х210х58, интерфейсы 1х Ethernet 10/100, 1х RS-232, 3х RS-485, 1х USB 2.0 HOST, 1х аудио вход, 1х аудио выход. Без корзин для модулей расширения. Предустановленная среда исполнения MasterSCADA 4D комплектация базовая на 1000 точек, клиент визуализации | C25: 80000 | D25: =C25*1.22 -> 97600
A26: ПЛК СТАБУР 10.М2K5 | B26: Программируемый логический контроллер ПЛК СТАБУР 10. Металлический корпус. Процессор 4х-ядерный ARM v8.2-A Cortex-A55, 64 бит, 2 ГГц; Видеоускоритель Mali-G52; ОЗУ 1 ГБ DDR4 1600 МГц 2 канала; FLASH память 4ГБ eMMC HS200; 1x слот microSD, 1x мини-USB OTG, часы реального времени. Дисплей 10.4'' TFT (1024х768); корпус для крепления на щит или на кронштейн 75х75 (VESA), габаритные размеры, мм 289х210х58, интерфейсы 1х Ethernet 10/100, 1х RS-232, 3х RS-485, 1х USB 2.0 HOST, 1х аудио вход, 1х аудио выход. Без корзин для модулей расширения. Предустановленная среда исполнения MasterSCADA 4D комплектация базовая на 2500 точек, клиент визуализации | C26: 76000 | D26: =C26*1.22 -> 92720
A27: ПЛК СТАБУР 10.М2K5 4/32 | B27: Программируемый логический контроллер ПЛК СТАБУР 10. Металлический корпус. Процессор 4х-ядерный ARM v8.2-A Cortex-A55, 64 бит, 2 ГГц; Видеоускоритель Mali-G52; ОЗУ 4 ГБ DDR4 1600 МГц 2 канала; FLASH память 32 ГБ eMMC HS200; 1x слот microSD, 1x мини-USB OTG, часы реального времени. Дисплей 10.4'' TFT (1024х768); корпус для крепления на щит или на кронштейн 75х75 (VESA), габаритные размеры, мм 289х210х58, интерфейсы 1х Ethernet 10/100, 1х RS-232, 3х RS-485, 1х USB 2.0 HOST, 1х аудио вход, 1х аудио выход. Без корзин для модулей расширения. Предустановленная среда исполнения MasterSCADA 4D комплектация базовая на 2500 точек, клиент визуализации | C27: 86000 | D27: =C27*1.22 -> 104920
A28: ПЛК СТАБУР 10.М5K0 | B28: Программируемый логический контроллер ПЛК СТАБУР 10. Металлический корпус. Процессор 4х-ядерный ARM v8.2-A Cortex-A55, 64 бит, 2 ГГц; Видеоускоритель Mali-G52; ОЗУ 1 ГБ DDR4 1600 МГц 2 канала; FLASH память 4ГБ eMMC HS200; 1x слот microSD, 1x мини-USB OTG, часы реального времени. Дисплей 10.4'' TFT (1024х768); корпус для крепления на щит или на кронштейн 75х75 (VESA), габаритные размеры, мм 289х210х58, интерфейсы 1х Ethernet 10/100, 1х RS-232, 3х RS-485, 1х USB 2.0 HOST, 1х аудио вход, 1х аудио выход. Без корзин для модулей расширения. Предустановленная среда исполнения MasterSCADA 4D комплектация базовая на 5000 точек, клиент визуализации | C28: 82000 | D28: =C28*1.22 -> 100040
A29: ПЛК СТАБУР 10.М5K0 4/32 | B29: Программируемый логический контроллер ПЛК СТАБУР 10. Металлический корпус. Процессор 4х-ядерный ARM v8.2-A Cortex-A55, 64 бит, 2 ГГц; Видеоускоритель Mali-G52; ОЗУ 4 ГБ DDR4 1600 МГц 2 канала; FLASH память 32 ГБ eMMC HS200; 1x слот microSD, 1x мини-USB OTG, часы реального времени. Дисплей 10.4'' TFT (1024х768); корпус для крепления на щит или на кронштейн 75х75 (VESA), габаритные размеры, мм 289х210х58, интерфейсы 1х Ethernet 10/100, 1х RS-232, 3х RS-485, 1х USB 2.0 HOST, 1х аудио вход, 1х аудио выход. Без корзин для модулей расширения. Предустановленная среда исполнения MasterSCADA 4D комплектация базовая на 5000 точек, клиент визуализации | C29: 92000 | D29: =C29*1.22 -> 112240
A30: ПЛК СТАБУР 10.М10К 4/32 | B30: Программируемый логический контроллер ПЛК СТАБУР 10. Металлический корпус. Процессор 4х-ядерный ARM v8.2-A Cortex-A55, 64 бит, 2 ГГц; Видеоускоритель Mali-G52; ОЗУ 4 ГБ DDR4 1600 МГц 2 канала; FLASH память 32 ГБ eMMC HS200; 1x слот microSD, 1x мини-USB OTG, часы реального времени. Дисплей 10.4'' TFT (1024х768); корпус для крепления на щит или на кронштейн 75х75 (VESA), габаритные размеры, мм 289х210х58, интерфейсы 1х Ethernet 10/100, 1х RS-232, 3х RS-485, 1х USB 2.0 HOST, 1х аудио вход, 1х аудио выход. Без корзин для модулей расширения. Предустановленная среда исполнения MasterSCADA 4D комплектация базовая на 10000 точек, клиент визуализации | E30: по запросу
A31: ПЛК СТАБУР 10.М0K5 (Х+Х+Х+PS24+Х+Х+Х+Х) | B31: Программируемый логический контроллер ПЛК СТАБУР 10 (Х+Х+Х+PS24+Х+Х+Х+Х), Пластиковый корпус. Процессор 4х-ядерный ARM v8.2-A Cortex-A55, 64 бит, 2 ГГц; Видеоускоритель Mali-G52; ОЗУ 1 ГБ DDR4 1600 МГц 2 канала; FLASH память 4ГБ eMMC HS200; 1x слот microSD, 1x мини-USB OTG, часы реального времени. Дисплей 10.1'' TFT (1024х600). Модуль расширения PS24 — модуль питания 24В установлен в слот №4.Корпус для крепления на щит, габаритные размеры, мм 260х210х93. Возможность установки до 7 модулей расширения. Предустановленная среда исполнения MasterSCADA 4D комплектация базовая на 500 точек, клиент визуализации | C31: 57000 | D31: =C31*1.22 -> 69540
A32: ПЛК СТАБУР 10.М0K5 4/32 (Х+Х+Х+PS24+Х+Х+Х+Х) | B32: Программируемый логический контроллер ПЛК СТАБУР 10 (Х+Х+Х+PS24+Х+Х+Х+Х), Пластиковый корпус. Процессор 4х-ядерный ARM v8.2-A Cortex-A55, 64 бит, 2 ГГц; Видеоускоритель Mali-G52; ОЗУ 4 ГБ DDR4 1600 МГц 2 канала; FLASH память 32 ГБ eMMC HS200; 1x слот microSD, 1x мини-USB OTG, часы реального времени. Дисплей 10.1'' TFT (1024х600). Модуль расширения PS24 — модуль питания 24В установлен в слот №4.Корпус для крепления на щит, габаритные размеры, мм 260х210х93. Возможность установки до 7 модулей расширения. Предустановленная среда исполнения MasterSCADA 4D комплектация базовая на 500 точек, клиент визуализации | C32: 67000 | D32: =C32*1.22 -> 81740
A33: ПЛК СТАБУР 10.М1K0 (Х+Х+Х+PS24+Х+Х+Х+Х) | B33: Программируемый логический контроллер ПЛК СТАБУР 10 (Х+Х+Х+PS24+Х+Х+Х+Х), Пластиковый корпус. Процессор 4х-ядерный ARM v8.2-A Cortex-A55, 64 бит, 2 ГГц; Видеоускоритель Mali-G52; ОЗУ 1 ГБ DDR4 1600 МГц 2 канала; FLASH память 4ГБ eMMC HS200; 1x слот microSD, 1x мини-USB OTG, часы реального времени. Дисплей 10.1'' TFT (1024х600). Модуль расширения PS24 — модуль питания 24В установлен в слот №4.Корпус для крепления на щит, габаритные размеры, мм 260х210х93. Возможность установки до 7 модулей расширения. Предустановленная среда исполнения MasterSCADA 4D комплектация базовая на 1000 точек, клиент визуализации | C33: 63000 | D33: =C33*1.22 -> 76860
A34: ПЛК СТАБУР 10.М1K0 4/32 (Х+Х+Х+PS24+Х+Х+Х+Х) | B34: Программируемый логический контроллер ПЛК СТАБУР 10 (Х+Х+Х+PS24+Х+Х+Х+Х), Пластиковый корпус. Процессор 4х-ядерный ARM v8.2-A Cortex-A55, 64 бит, 2 ГГц; Видеоускоритель Mali-G52; ОЗУ 4 ГБ DDR4 1600 МГц 2 канала; FLASH память 32 ГБ eMMC HS200; 1x слот microSD, 1x мини-USB OTG, часы реального времени. Дисплей 10.1'' TFT (1024х600). Модуль расширения PS24 — модуль питания 24В установлен в слот №4.Корпус для крепления на щит, габаритные размеры, мм 260х210х93. Возможность установки до 7 модулей расширения. Предустановленная среда исполнения MasterSCADA 4D комплектация базовая на 1000 точек, клиент визуализации | C34: 73000 | D34: =C34*1.22 -> 89060
A35: ПЛК СТАБУР 10.М2K5 (Х+Х+Х+PS24+Х+Х+Х+Х) | B35: Программируемый логический контроллер ПЛК СТАБУР 10 (Х+Х+Х+PS24+Х+Х+Х+Х), Пластиковый корпус. Процессор 4х-ядерный ARM v8.2-A Cortex-A55, 64 бит, 2 ГГц; Видеоускоритель Mali-G52; ОЗУ 1 ГБ DDR4 1600 МГц 2 канала; FLASH память 4ГБ eMMC HS200; 1x слот microSD, 1x мини-USB OTG, часы реального времени. Дисплей 10.1'' TFT (1024х600). Модуль расширения PS24 — модуль питания 24В установлен в слот №4.Корпус для крепления на щит, габаритные размеры, мм 260х210х93. Возможность установки до 7 модулей расширения. Предустановленная среда исполнения MasterSCADA 4D комплектация базовая на 2500 точек, клиент визуализации | C35: 69000 | D35: =C35*1.22 -> 84180
A36: ПЛК СТАБУР 10.М2K5 4/32 (Х+Х+Х+PS24+Х+Х+Х+Х) | B36: Программируемый логический контроллер ПЛК СТАБУР 10 (Х+Х+Х+PS24+Х+Х+Х+Х), Пластиковый корпус. Процессор 4х-ядерный ARM v8.2-A Cortex-A55, 64 бит, 2 ГГц; Видеоускоритель Mali-G52; ОЗУ 4 ГБ DDR4 1600 МГц 2 канала; FLASH память 32 ГБ eMMC HS200; 1x слот microSD, 1x мини-USB OTG, часы реального времени. Дисплей 10.1'' TFT (1024х600). Модуль расширения PS24 — модуль питания 24В установлен в слот №4.Корпус для крепления на щит, габаритные размеры, мм 260х210х93. Возможность установки до 7 модулей расширения. Предустановленная среда исполнения MasterSCADA 4D комплектация базовая на 2500 точек, клиент визуализации | C36: 79000 | D36: =C36*1.22 -> 96380
A37: ПЛК СТАБУР 10.М5K0 (Х+Х+Х+PS24+Х+Х+Х+Х) | B37: Программируемый логический контроллер ПЛК СТАБУР 10 (Х+Х+Х+PS24+Х+Х+Х+Х), Пластиковый корпус. Процессор 4х-ядерный ARM v8.2-A Cortex-A55, 64 бит, 2 ГГц; Видеоускоритель Mali-G52; ОЗУ 1 ГБ DDR4 1600 МГц 2 канала; FLASH память 4ГБ eMMC HS200; 1x слот microSD, 1x мини-USB OTG, часы реального времени. Дисплей 10.1'' TFT (1024х600). Модуль расширения PS24 — модуль питания 24В установлен в слот №4.Корпус для крепления на щит, габаритные размеры, мм 260х210х93. Возможность установки до 7 модулей расширения. Предустановленная среда исполнения MasterSCADA 4D комплектация базовая на 5000 точек, клиент визуализации | C37: 75000 | D37: =C37*1.22 -> 91500
A38: ПЛК СТАБУР 10.М5K0 4/32 (Х+Х+Х+PS24+Х+Х+Х+Х) | B38: Программируемый логический контроллер ПЛК СТАБУР 10 (Х+Х+Х+PS24+Х+Х+Х+Х), Пластиковый корпус. Процессор 4х-ядерный ARM v8.2-A Cortex-A55, 64 бит, 2 ГГц; Видеоускоритель Mali-G52; ОЗУ 4 ГБ DDR4 1600 МГц 2 канала; FLASH память 32 ГБ eMMC HS200; 1x слот microSD, 1x мини-USB OTG, часы реального времени. Дисплей 10.1'' TFT (1024х600). Модуль расширения PS24 — модуль питания 24В установлен в слот №4.Корпус для крепления на щит, габаритные размеры, мм 260х210х93. Возможность установки до 7 модулей расширения. Предустановленная среда исполнения MasterSCADA 4D комплектация базовая на 5000 точек, клиент визуализации | C38: 85000 | D38: =C38*1.22 -> 103700
A39: ПЛК СТАБУР 10.М10К 4/32 (Х+Х+Х+PS24+Х+Х+Х+Х) | B39: Программируемый логический контроллер ПЛК СТАБУР 10 (Х+Х+Х+PS24+Х+Х+Х+Х), Пластиковый корпус. Процессор 4х-ядерный ARM v8.2-A Cortex-A55, 64 бит, 2 ГГц; Видеоускоритель Mali-G52; ОЗУ 4 ГБ DDR4 1600 МГц 2 канала; FLASH память 32 ГБ eMMC HS200; 1x слот microSD, 1x мини-USB OTG, часы реального времени. Дисплей 10.1'' TFT (1024х600). Модуль расширения PS24 — модуль питания 24В установлен в слот №4.Корпус для крепления на щит, габаритные размеры, мм 260х210х93. Возможность установки до 7 модулей расширения. Предустановленная среда исполнения MasterSCADA 4D комплектация базовая на 10000 точек, клиент визуализации | E39: по запросу
A40: ПЛК СТАБУР 12.М0K5 | B40: Программируемый логический контроллер ПЛК СТАБУР 12. Металлический корпус. Процессор 4х-ядерный ARM v8.2-A Cortex-A55, 64 бит, 2 ГГц; Видеоускоритель Mali-G52; ОЗУ 1 ГБ DDR4 1600 МГц 2 канала; FLASH память 4ГБ eMMC HS200; 1x слот microSD, 1x мини-USB OTG, часы реального времени. Дисплей 12.1'' TFT (1024х768); корпус для крепления на щит или на кронштейн 75х75 (VESA), габаритные размеры, мм 293х267х45, интерфейсы 1х Ethernet 10/100, 1х RS-232, 3х RS-485, 1х USB 2.0 HOST, 1х аудио вход, 1х аудио выход. Без корзин для модулей расширения. Предустановленная среда исполнения MasterSCADA 4D комплектация базовая на 500 точек, клиент визуализации | C40: 68750 | D40: =C40*1.22 -> 83875
...

Sheet ПО СТАБУР 05-24 CODESYS
A1: ='ПЛК СТАБУР 05-24 CODESYS'!A1 -> 12.03.2026 Прайс лист на продукцию ПЛК/ПО/ПК СТАБУР ООО ПО «Промсвязь»
A2: Примеры полного условного обозначения прибора: ПО СТАБУР 21 панель оператора СТАБУР с экраном размером 21,5'', без модулей ввода-вывода и без корзины для их установки. Предустановленная среда исполнения CODESYS 3.5. ПО СТАБУР 05 (ETH232+AUSBH+RS485+PS24+WIFIBT+GSM+CAN+X) – Панель оператора СТАБУР с экраном размером 5'', с одной корзиной для модулей, с установленными модулями интерфейсов: в слоте №1 – ETH232, №2 – AUSBH №3 – RS485, №4 – PS24, №5 – WIFIBT, №6 – GSM, №7 – CAN. В слоте №8 модули отсутствуют. Предустановленная среда исполнения CODESYS 3.5. ПО СТАБУР 17 (GSM+CAN+Х+Х+WIFIBT+X+Х+Х) – Панель оператора СТАБУР с экраном размером 17'', с одной корзиной для модулей, с установленными модулями интерфейсов: в слоте №1 – GSM, №2 – CAN, №5 – WIFIBT. В слотах №3, №4 и №6, №7,№8 модули отсутствуют. Предустановленная среда исполнения CODESYS 3.5.
A3: Модель | B3: Описание | C3: Цена без НДС | D3: Цена С НДС 22%
A4: ПО СТАБУР 05 (ETH232+Х+Х+PS24+Х+Х+Х+Х) | B4: Панель оператора ПО СТАБУР 05 (ETH232+Х+Х+PS24+Х+Х+Х+Х), Пластиковый корпус. Процессор 4х-ядерный ARM v8.2-A Cortex-A55, 64 бит, 2 ГГц; Видеоускоритель Mali-G52; ОЗУ 1 ГБ DDR4 1600 МГц 2 канала; FLASH память 4ГБ eMMC HS200; 1x слот microSD, 1x мини-USB OTG, часы реального времени. Дисплей 5.0'' TFT (800х480). Модуль расширения ETH232 - модуль интерфейсов 1х Ethernet 10/100 Мбит и 1х RS-232 установлен в слот №1, PS24 — модуль питания 24В установлен в слот №4.Корпус для крепления на щит, габаритные размеры, мм 140x140x88. Возможность дополнительной установки до 5 модулей интерфейсов. Предустановленная среда исполнения CODESYS 3.5 | C4: 29650 | D4: =C4*1.22 -> 36173
A5: ПО СТАБУР 05 4/32 (ETH232+Х+Х+PS24+Х+Х+Х+Х) | B5: Панель оператора ПО СТАБУР 05 (ETH232+Х+Х+PS24+Х+Х+Х+Х), Пластиковый корпус. Процессор 4х-ядерный ARM v8.2-A Cortex-A55, 64 бит, 2 ГГц; Видеоускоритель Mali-G52; ОЗУ 4 ГБ DDR4 1600 МГц 2 канала; FLASH память 32 ГБ eMMC HS200; 1x слот microSD, 1x мини-USB OTG, часы реального времени. Дисплей 5.0'' TFT (800х480). Модуль расширения ETH232 - модуль интерфейсов 1х Ethernet 10/100 Мбит и 1х RS-232 установлен в слот №1, PS24 — модуль питания 24В установлен в слот №4.Корпус для крепления на щит, габаритные размеры, мм 140x140x88. Возможность дополнительной установки до 5 модулей интерфейсов. Предустановленная среда исполнения CODESYS 3.5 | C5: 39650 | D5: =C5*1.22 -> 48373
A6: ПО СТАБУР 07 (ETH232+Х+Х+PS24+Х+Х+Х+Х) | B6: Панель оператора ПО СТАБУР 07 (ETH232+Х+Х+PS24+Х+Х+Х+Х), Пластиковый корпус. Процессор 4х-ядерный ARM v8.2-A Cortex-A55, 64 бит, 2 ГГц; Видеоускоритель Mali-G52; ОЗУ 1 ГБ DDR4 1600 МГц 2 канала; FLASH память 4ГБ eMMC HS200; 1x слот microSD, 1x мини-USB OTG, часы реального времени. Дисплей 7.0'' TFT (800х480). Модуль расширения ETH232 - модуль интерфейсов 1х Ethernet 10/100 Мбит и 1х RS-232 установлен в слот №1, модуль расширения PS24 — модуль питания 24В установлен в слот №4.Корпус для крепления на щит, габаритные размеры, мм 185х160х91. Возможность дополнительной установки до 5 модулей интерфейсов. Предустановленная среда исполнения CODESYS 3.5 | C6: 37450 | D6: =C6*1.22 -> 45689
A7: ПО СТАБУР 07 4/32 (ETH232+Х+Х+PS24+Х+Х+Х+Х) | B7: Панель оператора ПО СТАБУР 07 (ETH232+Х+Х+PS24+Х+Х+Х+Х), Пластиковый корпус. Процессор 4х-ядерный ARM v8.2-A Cortex-A55, 64 бит, 2 ГГц; Видеоускоритель Mali-G52; ОЗУ 4 ГБ DDR4 1600 МГц 2 канала; FLASH память 32 ГБ eMMC HS200; 1x слот microSD, 1x мини-USB OTG, часы реального времени. Дисплей 7.0'' TFT (800х480). Модуль расширения ETH232 - модуль интерфейсов 1х Ethernet 10/100 Мбит и 1х RS-232 установлен в слот №1, модуль расширения PS24 — модуль питания 24В установлен в слот №4.Корпус для крепления на щит, габаритные размеры, мм 185х160х91. Возможность дополнительной установки до 5 модулей интерфейсов. Предустановленная среда исполнения CODESYS 3.5 | C7: 47450 | D7: =C7*1.22 -> 57889
A8: ПО СТАБУР 10 | B8: Панель оператора ПО СТАБУР 10. Процессор 4х-ядерный ARM v8.2-A Cortex-A55, 64 бит, 2 ГГц; Видеоускоритель Mali-G52; ОЗУ 1 ГБ DDR4 1600 МГц 2 канала; FLASH память 4ГБ eMMC HS200; 1x слот microSD, 1x мини-USB OTG, часы реального времени. Дисплей 10.4'' TFT (1024х768); корпус для крепления на щит или на кронштейн 75х75 (VESA), габаритные размеры, мм 289х210х58, интерфейсы 1х Ethernet 10/100, 1х RS-232, 3х RS-485, 1х USB 2.0 HOST, 1х аудио вход, 1х аудио выход. Без корзин для модулей расширения. Предустановленная среда исполнения CODESYS 3.5 | C8: 51450 | D8: =C8*1.22 -> 62769
A9: ПО СТАБУР 10 4/32 | B9: Панель оператора ПО СТАБУР 10. Процессор 4х-ядерный ARM v8.2-A Cortex-A55, 64 бит, 2 ГГц; Видеоускоритель Mali-G52; ОЗУ 4 ГБ DDR4 1600 МГц 2 канала; FLASH память 32 ГБ eMMC HS200; 1x слот microSD, 1x мини-USB OTG, часы реального времени. Дисплей 10.4'' TFT (1024х768); корпус для крепления на щит или на кронштейн 75х75 (VESA), габаритные размеры, мм 289х210х58, интерфейсы 1х Ethernet 10/100, 1х RS-232, 3х RS-485, 1х USB 2.0 HOST, 1х аудио вход, 1х аудио выход. Без корзин для модулей расширения. Предустановленная среда исполнения CODESYS 3.5 | C9: 61450 | D9: =C9*1.22 -> 74969
A10: ПО СТАБУР 10 (ETH232+Х+Х+PS24+Х+Х+Х+Х) | B10: Панель оператора ПО СТАБУР 10 (ETH232+Х+Х+PS24+Х+Х+Х+Х), Пластиковый корпус. Процессор 4х-ядерный ARM v8.2-A Cortex-A55, 64 бит, 2 ГГц; Видеоускоритель Mali-G52; ОЗУ 1 ГБ DDR4 1600 МГц 2 канала; FLASH память 4ГБ eMMC HS200; 1x слот microSD, 1x мини-USB OTG, часы реального времени. Дисплей 10.1'' TFT (1024х600). Модуль расширения ETH232 - модуль интерфейсов 1х Ethernet 10/100 Мбит и 1х RS-232 установлен в слот №1, модуль расширения PS24 — модуль питания 24В установлен в слот №4.Корпус для крепления на щит, габаритные размеры, мм 260х210х93. Возможность дополнительной установки до 5 модулей интерфейсов. Предустановленная среда исполнения CODESYS 3.5 | C10: 44450 | D10: =C10*1.22 -> 54229
A11: ПО СТАБУР 10 4/32 (ETH232+Х+Х+PS24+Х+Х+Х+Х) | B11: Панель оператора ПО СТАБУР 10 (ETH232+Х+Х+PS24+Х+Х+Х+Х), Пластиковый корпус. Процессор 4х-ядерный ARM v8.2-A Cortex-A55, 64 бит, 2 ГГц; Видеоускоритель Mali-G52; ОЗУ 4 ГБ DDR4 1600 МГц 2 канала; FLASH память 32 ГБ eMMC HS200; 1x слот microSD, 1x мини-USB OTG, часы реального времени. Дисплей 10.1'' TFT (1024х600). Модуль расширения ETH232 - модуль интерфейсов 1х Ethernet 10/100 Мбит и 1х RS-232 установлен в слот №1, модуль расширения PS24 — модуль питания 24В установлен в слот №4.Корпус для крепления на щит, габаритные размеры, мм 260х210х93. Возможность дополнительной установки до 5 модулей интерфейсов. Предустановленная среда исполнения CODESYS 3.5 | C11: 54450 | D11: =C11*1.22 -> 66429
A12: ПО СТАБУР 12 | B12: Панель оператора ПО СТАБУР 12. Процессор 4х-ядерный ARM v8.2-A Cortex-A55, 64 бит, 2 ГГц; Видеоускоритель Mali-G52; ОЗУ 1 ГБ DDR4 1600 МГц 2 канала; FLASH память 4ГБ eMMC HS200; 1x слот microSD, 1x мини-USB OTG, часы реального времени. Дисплей 12.1'' TFT (1024х768); корпус для крепления на щит или на кронштейн 75х75 (VESA), габаритные размеры, мм 293х267х45, интерфейсы 1х Ethernet 10/100, 1х RS-232, 3х RS-485, 1х USB 2.0 HOST, 1х аудио вход, 1х аудио выход. Без корзин для модулей расширения. Предустановленная среда исполнения CODESYS 3.5 | C12: 53750 | D12: =C12*1.22 -> 65575
A13: ПО СТАБУР 12 4/32 | B13: Панель оператора ПО СТАБУР 12. Процессор 4х-ядерный ARM v8.2-A Cortex-A55, 64 бит, 2 ГГц; Видеоускоритель Mali-G52; ОЗУ 4 ГБ DDR4 1600 МГц 2 канала; FLASH память 32 ГБ eMMC HS200; 1x слот microSD, 1x мини-USB OTG, часы реального времени. Дисплей 12.1'' TFT (1024х768); корпус для крепления на щит или на кронштейн 75х75 (VESA), габаритные размеры, мм 293х267х45, интерфейсы 1х Ethernet 10/100, 1х RS-232, 3х RS-485, 1х USB 2.0 HOST, 1х аудио вход, 1х аудио выход. Без корзин для модулей расширения. Предустановленная среда исполнения CODESYS 3.5 | C13: 63750 | D13: =C13*1.22 -> 77775
A14: ПО СТАБУР 12 (Х+Х+Х+Х+Х+Х+Х+Х) | B14: Панель оператора ПО СТАБУР 12. Процессор 4х-ядерный ARM v8.2-A Cortex-A55, 64 бит, 2 ГГц; Видеоускоритель Mali-G52; ОЗУ 1 ГБ DDR4 1600 МГц 2 канала; FLASH память 4ГБ eMMC HS200; 1x слот microSD, 1x мини-USB OTG, часы реального времени. Дисплей 12.1'' TFT (1024х768); корпус для крепления на щит, габаритные размеры, мм 293х267х94, интерфейсы 1х Ethernet 10/100, 1х RS-232, 3х RS-485, 1х USB 2.0 HOST, 1х аудио вход, 1х аудио выход. 1 корзина на 8 модулей расширения. Возможность дополнительной установки до 3 модулей интерфейсов. Предустановленная среда исполнения CODESYS 3.5 | C14: 53750 | D14: =C14*1.22 -> 65575
A15: ПО СТАБУР 12 4/32 (Х+Х+Х+Х+Х+Х+Х+Х) | B15: Панель оператора ПО СТАБУР 12. Процессор 4х-ядерный ARM v8.2-A Cortex-A55, 64 бит, 2 ГГц; Видеоускоритель Mali-G52; ОЗУ 4 ГБ DDR4 1600 МГц 2 канала; FLASH память 32 ГБ eMMC HS200; 1x слот microSD, 1x мини-USB OTG, часы реального времени. Дисплей 12.1'' TFT (1024х768); корпус для крепления на щит, габаритные размеры, мм 293х267х94, интерфейсы 1х Ethernet 10/100, 1х RS-232, 3х RS-485, 1х USB 2.0 HOST, 1х аудио вход, 1х аудио выход. 1 корзина на 8 модулей расширения. Возможность дополнительной установки до 3 модулей интерфейсов. Предустановленная среда исполнения CODESYS 3.5 | C15: 63750 | D15: =C15*1.22 -> 77775
... A35: ПО СТАБУР 24 4/32 (Х+Х+Х+Х+Х+Х+Х+Х) | B35: Панель оператора ПО СТАБУР 24. Процессор 4х-ядерный ARM v8.2-A Cortex-A55, 64 бит, 2 ГГц; Видеоускоритель Mali-G52; ОЗУ 4 ГБ DDR4 1600 МГц 2 канала; FLASH память 32 ГБ eMMC HS200; 1x слот microSD, 1x мини-USB OTG, часы реального времени. Дисплей 24'' TFT (1920х1080); корпус для крепления на щит, интерфейсы 1х Ethernet 10/100, 1х RS-232, 3х RS-485, 1х USB 2.0 HOST, 1х аудио вход, 1х аудио выход. 1 корзина на 8 модулей расширения. Возможность дополнительной установки до 3 модулей интерфейсов. Предустановленная среда исполнения CODESYS 3.5 | C35: 134500 | D35: =C35*1.22 -> 164090

Sheet ПО СТАБУР 05-24 MasterSCADA 4D
A1: ='ПЛК СТАБУР 05-24 CODESYS'!A1 -> 12.03.2026 Прайс лист на продукцию ПЛК/ПО/ПК СТАБУР ООО ПО «Промсвязь»
A2: Примеры полного условного обозначения прибора: ПО СТАБУР 21.M0K5 панель оператора СТАБУР с экраном размером 21,5'', без модулей ввода-вывода и без корзины для их установки. Предустановленная среда исполнения MasterSCADA 4D на 500 точек. ПО СТАБУР 05.М2К5 (ETH232+AUSBH+RS485+PS24+WIFIBT+GSM+CAN+X) – Панель оператора СТАБУР с экраном размером 5'', с одной корзиной для модулей с установленными модулями интерфейсов: в слоте №1 – ETH232, №2 – AUSBH №3 – RS485, №4 – PS24, №5 – WIFIBT, №6 – GSM, №7 – CAN. В слоте №8 модули отсутствуют. Предустановленная среда исполнения MasterSCADA 4D на 2500 точек. ПО СТАБУР 17.М5К0 (GSM+CAN+Х+Х+WIFIBT+X+Х+Х) – Панель оператора СТАБУР с экраном размером 17'', с одной корзиной для модулей, с установленными модулями интерфейсов: в слоте №1 – GSM, №2 – CAN, №5 – WIFIBT. В слотах №3, №4 и №6, №7,№8 модули отсутствуют. Предустановленная среда исполнения MasterSCADA 4D на 5000 точек.
A3: Модель | B3: Описание | C3: Цена без НДС | D3: Цена С НДС 22%
A4: ПО СТАБУР 05.М0К5 (ETH232+Х+Х+PS24+Х+Х+Х+Х) | B4: Панель оператора ПО СТАБУР 05 (ETH232+Х+Х+PS24+Х+Х+Х+Х), Пластиковый корпус. Процессор 4х-ядерный ARM v8.2-A Cortex-A55, 64 бит, 2 ГГц; Видеоускоритель Mali-G52; ОЗУ 1 ГБ DDR4 1600 МГц 2 канала; FLASH память 4ГБ eMMC HS200; 1x слот microSD, 1x мини-USB OTG, часы реального времени. Дисплей 5.0'' TFT (800х480). Модуль расширения ETH232 - модуль интерфейсов 1х Ethernet 10/100 Мбит и 1х RS-232 установлен в слот №1, PS24 — модуль питания 24В установлен в слот №4.Корпус для крепления на щит, габаритные размеры, мм 140x140x88. Возможность дополнительной установки до 5 модулей интерфейсов. Предустановленная среда исполнения MasterSCADA 4D комплектация базовая на 500 точек, клиент визуализации. | C4: 44650 | D4: =C4*1.22 -> 54473
A5: ПО СТАБУР 05.М0К5 4/32 (ETH232+Х+Х+PS24+Х+Х+Х+Х) | B5: Панель оператора ПО СТАБУР 05 (ETH232+Х+Х+PS24+Х+Х+Х+Х), Пластиковый корпус. Процессор 4х-ядерный ARM v8.2-A Cortex-A55, 64 бит, 2 ГГц; Видеоускоритель Mali-G52; ОЗУ 4 ГБ DDR4 1600 МГц 2 канала; FLASH память 32 ГБ eMMC HS200; 1x слот microSD, 1x мини-USB OTG, часы реального времени. Дисплей 5.0'' TFT (800х480). Модуль расширения ETH232 - модуль интерфейсов 1х Ethernet 10/100 Мбит и 1х RS-232 установлен в слот №1, PS24 — модуль питания 24В установлен в слот №4.Корпус для крепления на щит, габаритные размеры, мм 140x140x88. Возможность дополнительной установки до 5 модулей интерфейсов. Предустановленная среда исполнения MasterSCADA 4D комплектация базовая на 500 точек, клиент визуализации. | C5: 54650 | D5: =C5*1.22 -> 66673
A6: ПО СТАБУР 05.М1K0 (ETH232+Х+Х+PS24+Х+Х+Х+Х) | B6: Панель оператора ПО СТАБУР 05 (ETH232+Х+Х+PS24+Х+Х+Х+Х), Пластиковый корпус. Процессор 4х-ядерный ARM v8.2-A Cortex-A55, 64 бит, 2 ГГц; Видеоускоритель Mali-G52; ОЗУ 1 ГБ DDR4 1600 МГц 2 канала; FLASH память 4ГБ eMMC HS200; 1x слот microSD, 1x мини-USB OTG, часы реального времени. Дисплей 5.0'' TFT (800х480). Модуль расширения ETH232 - модуль интерфейсов 1х Ethernet 10/100 Мбит и 1х RS-232 установлен в слот №1, PS24 — модуль питания 24В установлен в слот №4.Корпус для крепления на щит, габаритные размеры, мм 140x140x88. Возможность дополнительной установки до 5 модулей интерфейсов. Предустановленная среда исполнения MasterSCADA 4D комплектация базовая на 1000 точек, клиент визуализации | C6: 50650 | D6: =C6*1.22 -> 61793
A7: ПО СТАБУР 05.М1K0 4/32 (ETH232+Х+Х+PS24+Х+Х+Х+Х) | B7: Панель оператора ПО СТАБУР 05 (ETH232+Х+Х+PS24+Х+Х+Х+Х), Пластиковый корпус. Процессор 4х-ядерный ARM v8.2-A Cortex-A55, 64 бит, 2 ГГц; Видеоускоритель Mali-G52; ОЗУ 4 ГБ DDR4 1600 МГц 2 канала; FLASH память 32 ГБ eMMC HS200; 1x слот microSD, 1x мини-USB OTG, часы реального времени. Дисплей 5.0'' TFT (800х480). Модуль расширения ETH232 - модуль интерфейсов 1х Ethernet 10/100 Мбит и 1х RS-232 установлен в слот №1, PS24 — модуль питания 24В установлен в слот №4.Корпус для крепления на щит, габаритные размеры, мм 140x140x88. Возможность дополнительной установки до 5 модулей интерфейсов. Предустановленная среда исполнения MasterSCADA 4D комплектация базовая на 1000 точек, клиент визуализации | C7: 60650 | D7: =C7*1.22 -> 73993
A8: ПО СТАБУР 05.М2K5 (ETH232+Х+Х+PS24+Х+Х+Х+Х) | B8: Панель оператора ПО СТАБУР 05 (ETH232+Х+Х+PS24+Х+Х+Х+Х), Пластиковый корпус. Процессор 4х-ядерный ARM v8.2-A Cortex-A55, 64 бит, 2 ГГц; Видеоускоритель Mali-G52; ОЗУ 1 ГБ DDR4 1600 МГц 2 канала; FLASH память 4ГБ eMMC HS200; 1x слот microSD, 1x мини-USB OTG, часы реального времени. Дисплей 5.0'' TFT (800х480). Модуль расширения ETH232 - модуль интерфейсов 1х Ethernet 10/100 Мбит и 1х RS-232 установлен в слот №1, PS24 — модуль питания 24В установлен в слот №4.Корпус для крепления на щит, габаритные размеры, мм 140x140x88. Возможность дополнительной установки до 5 модулей интерфейсов. Предустановленная среда исполнения MasterSCADA 4D комплектация базовая на 2500 точек, клиент визуализации | C8: 56650 | D8: =C8*1.22 -> 69113
A9: ПО СТАБУР 05.М2K5 4/32 (ETH232+Х+Х+PS24+Х+Х+Х+Х) | B9: Панель оператора ПО СТАБУР 05 (ETH232+Х+Х+PS24+Х+Х+Х+Х), Пластиковый корпус. Процессор 4х-ядерный ARM v8.2-A Cortex-A55, 64 бит, 2 ГГц; Видеоускоритель Mali-G52; ОЗУ 4 ГБ DDR4 1600 МГц 2 канала; FLASH память 32 ГБ eMMC HS200; 1x слот microSD, 1x мини-USB OTG, часы реального времени. Дисплей 5.0'' TFT (800х480). Модуль расширения ETH232 - модуль интерфейсов 1х Ethernet 10/100 Мбит и 1х RS-232 установлен в слот №1, PS24 — модуль питания 24В установлен в слот №4.Корпус для крепления на щит, габаритные размеры, мм 140x140x88. Возможность дополнительной установки до 5 модулей интерфейсов. Предустановленная среда исполнения MasterSCADA 4D комплектация базовая на 2500 точек, клиент визуализации | C9: 66650 | D9: =C9*1.22 -> 81313
A10: ПО СТАБУР 05.М5K0 (ETH232+Х+Х+PS24+Х+Х+Х+Х) | B10: Панель оператора ПО СТАБУР 05 (ETH232+Х+Х+PS24+Х+Х+Х+Х), Пластиковый корпус. Процессор 4х-ядерный ARM v8.2-A Cortex-A55, 64 бит, 2 ГГц; Видеоускоритель Mali-G52; ОЗУ 1 ГБ DDR4 1600 МГц 2 канала; FLASH память 4ГБ eMMC HS200; 1x слот microSD, 1x мини-USB OTG, часы реального времени. Дисплей 5.0'' TFT (800х480). Модуль расширения ETH232 - модуль интерфейсов 1х Ethernet 10/100 Мбит и 1х RS-232 установлен в слот №1, PS24 — модуль питания 24В установлен в слот №4.Корпус для крепления на щит, габаритные размеры, мм 140x140x88. Возможность дополнительной установки до 5 модулей интерфейсов. Предустановленная среда исполнения MasterSCADA 4D комплектация базовая на 5000 точек, клиент визуализации | C10: 62650 | D10: =C10*1.22 -> 76433
A11: ПО СТАБУР 05.М5K0 4/32 (ETH232+Х+Х+PS24+Х+Х+Х+Х) | B11: Панель оператора ПО СТАБУР 05 (ETH232+Х+Х+PS24+Х+Х+Х+Х), Пластиковый корпус. Процессор 4х-ядерный ARM v8.2-A Cortex-A55, 64 бит, 2 ГГц; Видеоускоритель Mali-G52; ОЗУ 4 ГБ DDR4 1600 МГц 2 канала; FLASH память 32 ГБ eMMC HS200; 1x слот microSD, 1x мини-USB OTG, часы реального времени. Дисплей 5.0'' TFT (800х480). Модуль расширения ETH232 - модуль интерфейсов 1х Ethernet 10/100 Мбит и 1х RS-232 установлен в слот №1, PS24 — модуль питания 24В установлен в слот №4.Корпус для крепления на щит, габаритные размеры, мм 140x140x88. Возможность дополнительной установки до 5 модулей интерфейсов. Предустановленная среда исполнения MasterSCADA 4D комплектация базовая на 5000 точек, клиент визуализации | C11: 72650 | D11: =C11*1.22 -> 88633
A12: ПО СТАБУР 05.М10К 4/32 (ETH232+Х+Х+PS24+Х+Х+Х+Х) | B12: Панель оператора ПО СТАБУР 05 (ETH232+Х+Х+PS24+Х+Х+Х+Х), Пластиковый корпус. Процессор 4х-ядерный ARM v8.2-A Cortex-A55, 64 бит, 2 ГГц; Видеоускоритель Mali-G52; ОЗУ 4 ГБ DDR4 1600 МГц 2 канала; FLASH память 32 ГБ eMMC HS200; 1x слот microSD, 1x мини-USB OTG, часы реального времени. Дисплей 5.0'' TFT (800х480). Модуль расширения ETH232 - модуль интерфейсов 1х Ethernet 10/100 Мбит и 1х RS-232 установлен в слот №1, PS24 — модуль питания 24В установлен в слот №4.Корпус для крепления на щит, габаритные размеры, мм 140x140x88. Возможность дополнительной установки до 5 модулей интерфейсов. Предустановленная среда исполнения MasterSCADA 4D комплектация базовая на 10000 точек, клиент визуализации | E12: по запросу
A13: ПО СТАБУР 07.М0К5 (ETH232+Х+Х+PS24+Х+Х+Х+Х) | B13: Панель оператора ПО СТАБУР 07 (ETH232+Х+Х+PS24+Х+Х+Х+Х), Пластиковый корпус. Процессор 4х-ядерный ARM v8.2-A Cortex-A55, 64 бит, 2 ГГц; Видеоускоритель Mali-G52; ОЗУ 1 ГБ DDR4 1600 МГц 2 канала; FLASH память 4ГБ eMMC HS200; 1x слот microSD, 1x мини-USB OTG, часы реального времени. Дисплей 7.0'' TFT (800х480). Модуль расширения ETH232 - модуль интерфейсов 1х Ethernet 10/100 Мбит и 1х RS-232 установлен в слот №1, модуль расширения PS24 — модуль питания 24В установлен в слот №4.Корпус для крепления на щит, габаритные размеры, мм 185х160х91. Возможность дополнительной установки до 5 модулей интерфейсов. Предустановленная среда исполнения MasterSCADA 4D комплектация базовая на 500 точек, клиент визуализации | C13: 52450 | D13: =C13*1.22 -> 63989
A14: ПО СТАБУР 07.М0К5 4/32 (ETH232+Х+Х+PS24+Х+Х+Х+Х) | B14: Панель оператора ПО СТАБУР 07 (ETH232+Х+Х+PS24+Х+Х+Х+Х), Пластиковый корпус. Процессор 4х-ядерный ARM v8.2-A Cortex-A55, 64 бит, 2 ГГц; Видеоускоритель Mali-G52; ОЗУ 1 ГБ DDR4 1600 МГц 2 канала; FLASH память 4ГБ eMMC HS200; 1x слот microSD, 1x мини-USB OTG, часы реального времени. Дисплей 7.0'' TFT (800х480). Модуль расширения ETH232 - модуль интерфейсов 1х Ethernet 10/100 Мбит и 1х RS-232 установлен в слот №1, модуль расширения PS24 — модуль питания 24В установлен в слот №4.Корпус для крепления на щит, габаритные размеры, мм 185х160х91. Возможность дополнительной установки до 5 модулей интерфейсов. Предустановленная среда исполнения MasterSCADA 4D комплектация базовая на 500 точек, клиент визуализации | C14: 62450 | D14: =C14*1.22 -> 76189
A15: ПО СТАБУР 07.М1K0 (ETH232+Х+Х+PS24+Х+Х+Х+Х) | B15: Панель оператора ПО СТАБУР 07 (ETH232+Х+Х+PS24+Х+Х+Х+Х), Пластиковый корпус. Процессор 4х-ядерный ARM v8.2-A Cortex-A55, 64 бит, 2 ГГц; Видеоускоритель Mali-G52; ОЗУ 1 ГБ DDR4 1600 МГц 2 канала; FLASH память 4ГБ eMMC HS200; 1x слот microSD, 1x мини-USB OTG, часы реального времени. Дисплей 7.0'' TFT (800х480). Модуль расширения ETH232 - модуль интерфейсов 1х Ethernet 10/100 Мбит и 1х RS-232 установлен в слот №1, модуль расширения PS24 — модуль питания 24В установлен в слот №4.Корпус для крепления на щит, габаритные размеры, мм 185х160х91. Возможность дополнительной установки до 5 модулей интерфейсов. Предустановленная среда исполнения MasterSCADA 4D комплектация базовая на 1000 точек, клиент визуализации | C15: 58450 | D15: =C15*1.22 -> 71309
A16: ПО СТАБУР 07.М1K0 4/32 (ETH232+Х+Х+PS24+Х+Х+Х+Х) | B16: Панель оператора ПО СТАБУР 07 (ETH232+Х+Х+PS24+Х+Х+Х+Х), Пластиковый корпус. Процессор 4х-ядерный ARM v8.2-A Cortex-A55, 64 бит, 2 ГГц; Видеоускоритель Mali-G52; ОЗУ 1 ГБ DDR4 1600 МГц 2 канала; FLASH память 4ГБ eMMC HS200; 1x слот microSD, 1x мини-USB OTG, часы реального времени. Дисплей 7.0'' TFT (800х480). Модуль расширения ETH232 - модуль интерфейсов 1х Ethernet 10/100 Мбит и 1х RS-232 установлен в слот №1, модуль расширения PS24 — модуль питания 24В установлен в слот №4.Корпус для крепления на щит, габаритные размеры, мм 185х160х91. Возможность дополнительной установки до 5 модулей интерфейсов. Предустановленная среда исполнения MasterSCADA 4D комплектация базовая на 1000 точек, клиент визуализации | C16: 68450 | D16: =C16*1.22 -> 83509
A17: ПО СТАБУР 07.М2K5 (ETH232+Х+Х+PS24+Х+Х+Х+Х) | B17: Панель оператора ПО СТАБУР 07 (ETH232+Х+Х+PS24+Х+Х+Х+Х), Пластиковый корпус. Процессор 4х-ядерный ARM v8.2-A Cortex-A55, 64 бит, 2 ГГц; Видеоускоритель Mali-G52; ОЗУ 1 ГБ DDR4 1600 МГц 2 канала; FLASH память 4ГБ eMMC HS200; 1x слот microSD, 1x мини-USB OTG, часы реального времени. Дисплей 7.0'' TFT (800х480). Модуль расширения ETH232 - модуль интерфейсов 1х Ethernet 10/100 Мбит и 1х RS-232 установлен в слот №1, модуль расширения PS24 — модуль питания 24В установлен в слот №4.Корпус для крепления на щит, габаритные размеры, мм 185х160х91. Возможность дополнительной установки до 5 модулей интерфейсов. Предустановленная среда исполнения MasterSCADA 4D комплектация базовая на 2500 точек, клиент визуализации | C17: 64450 | D17: =C17*1.22 -> 78629
A18: ПО СТАБУР 07.М2K5 4/32 (ETH232+Х+Х+PS24+Х+Х+Х+Х) | B18: Панель оператора ПО СТАБУР 07 (ETH232+Х+Х+PS24+Х+Х+Х+Х), Пластиковый корпус. Процессор 4х-ядерный ARM v8.2-A Cortex-A55, 64 бит, 2 ГГц; Видеоускоритель Mali-G52; ОЗУ 4 ГБ DDR4 1600 МГц 2 канала; FLASH память 32 ГБ eMMC HS200; 1x слот microSD, 1x мини-USB OTG, часы реального времени. Дисплей 7.0'' TFT (800х480). Модуль расширения ETH232 - модуль интерфейсов 1х Ethernet 10/100 Мбит и 1х RS-232 установлен в слот №1, модуль расширения PS24 — модуль питания 24В установлен в слот №4.Корпус для крепления на щит, габаритные размеры, мм 185х160х91. Возможность дополнительной установки до 5 модулей интерфейсов. Предустановленная среда исполнения MasterSCADA 4D комплектация базовая на 2500 точек, клиент визуализации | C18: 74450 | D18: =C18*1.22 -> 90829
